<?xml version="1.0" ?>
<!-- =================================================================================== -->
<!-- |    This document was autogenerated by xacro from fr01.urdf.xacro                | -->
<!-- |    EDITING THIS FILE BY HAND IS NOT RECOMMENDED                                 | -->
<!-- =================================================================================== -->
<robot name="fr01" xmlns:xacro="http://ros.org/wiki/xacro">
  <material name="black">
    <color rgba="0.0 0.0 0.0 1.0"/>
  </material>
  <material name="blue">
    <color rgba="0.0 0.0 0.8 1.0"/>
  </material>
  <material name="green">
    <color rgba="0.0 0.8 0.0 1.0"/>
  </material>
  <material name="grey">
    <color rgba="0.2 0.2 0.2 1.0"/>
  </material>
  <material name="orange">
    <color rgba="1.0 0.423529411765 0.0392156862745 1.0"/>
  </material>
  <material name="brown">
    <color rgba="0.870588235294 0.811764705882 0.764705882353 1.0"/>
  </material>
  <material name="red">
    <color rgba="0.8 0.0 0.0 1.0"/>
  </material>
  <material name="white">
    <color rgba="1.0 1.0 1.0 1.0"/>
  </material>
  <!--==================== Link & Joint ====================-->
  <!-- Body -->
  <link name="fake_base_footprint"/>
  <joint name="base_link_joint" type="fixed">
    <origin rpy="0 0 0" xyz="0 0 0.370"/>
    <parent link="fake_base_footprint"/>
    <child link="base_link"/>
  </joint>
  <link name="base_link">
    <visual>
      <origin rpy="0 0 -1.57079637" xyz="0 0 0"/>
      <geometry>
        <mesh filename="package://fr01_description/meshes/visual/base_link.dae"/>
      </geometry>
    </visual>
    <collision>
      <origin rpy="0 0 -1.57079637" xyz="0 0 0"/>
      <geometry>
        <mesh filename="package://fr01_description/meshes/collision/base_link.stl"/>
      </geometry>
    </collision>
    <inertial>
      <mass value="6.441"/>
      <inertia ixx="0.004" ixy="0.000000000792" ixz="-0.000000001557" iyy="0.002" iyz="-0.0000000001274" izz="0.005"/>
    </inertial>
  </link>
  <!-- Rocker -->
  <joint name="rocker_right_joint" type="revolute">
    <origin rpy="0 0 0" xyz="0 -0.213 0.028 "/>
    <parent link="base_link"/>
    <child link="rocker_right_link"/>
    <axis xyz="0 1 0"/>
    <dynamics dampint="0.7" friction="0.7"/>
    <limit effort="30.0" lower="-1.57079637" upper="1.57079637" velocity="6.28318548"/>
  </joint>
  <link name="rocker_right_link">
    <visual>
      <origin rpy="0 0 0" xyz="0 0 0"/>
      <geometry>
        <mesh filename="package://fr01_description/meshes/visual/rocker_right_link.dae"/>
      </geometry>
    </visual>
    <collision>
      <origin rpy="0 0 0" xyz="0 0 0"/>
      <geometry>
        <mesh filename="package://fr01_description/meshes/collision/rocker_right_link.stl"/>
      </geometry>
    </collision>
    <inertial>
      <mass value="2.088"/>
      <inertia ixx="0.0002582" ixy="-0.0000001417" ixz="-0.00004954" iyy="0.0004952" iyz="0.00000007736" izz="0.0003856"/>
    </inertial>
  </link>
  <joint name="rocker_left_joint" type="revolute">
    <origin rpy="0 0 0" xyz="0 0.213 0.028 "/>
    <parent link="base_link"/>
    <child link="rocker_left_link"/>
    <axis xyz="0 1 0"/>
    <dynamics dampint="0.7" friction="0.7"/>
    <limit effort="30.0" lower="-1.57079637" upper="1.57079637" velocity="6.28318548"/>
  </joint>
  <link name="rocker_left_link">
    <visual>
      <origin rpy="0 0 0" xyz="0 0 0"/>
      <geometry>
        <mesh filename="package://fr01_description/meshes/visual/rocker_left_link.dae"/>
      </geometry>
    </visual>
    <collision>
      <origin rpy="0 0 0" xyz="0 0 0"/>
      <geometry>
        <mesh filename="package://fr01_description/meshes/collision/rocker_left_link.stl"/>
      </geometry>
    </collision>
    <inertial>
      <mass value="2.088"/>
      <inertia ixx="0.0002507" ixy="0.0000001419" ixz="-0.00004954" iyy="0.0004952" iyz="-0.0004669" izz="0.0003932"/>
    </inertial>
  </link>
  <!-- Bogie -->
  <joint name="bogie_right_joint" type="revolute">
    <origin rpy="0 0 3.14159274" xyz="0.2 -0.019945 -0.15"/>
    <parent link="rocker_right_link"/>
    <child link="bogie_right_link"/>
    <axis xyz="0 1 0"/>
    <dynamics dampint="0.7" friction="0.7"/>
    <limit effort="30.0" lower="-1.57079637" upper="1.57079637" velocity="6.28318548"/>
  </joint>
  <link name="bogie_right_link">
    <visual>
      <origin rpy="0 0 0" xyz="0 0 0"/>
      <geometry>
        <mesh filename="package://fr01_description/meshes/visual/bogie_right_link.dae"/>
      </geometry>
    </visual>
    <collision>
      <origin rpy="0 0 0" xyz="0 0 0"/>
      <geometry>
        <mesh filename="package://fr01_description/meshes/collision/bogie_right_link.stl"/>
      </geometry>
    </collision>
    <inertial>
      <mass value="3.374"/>
      <inertia ixx="0.002" ixy="0.0000006258" ixz="-0.000002349" iyy="0.002" iyz="-0.0000001149" izz="0.003"/>
    </inertial>
  </link>
  <joint name="bogie_left_joint" type="revolute">
    <origin rpy="0 0 3.14159274" xyz="0.2 0.019945 -0.15"/>
    <parent link="rocker_left_link"/>
    <child link="bogie_left_link"/>
    <axis xyz="0 1 0"/>
    <dynamics dampint="0.7" friction="0.7"/>
    <limit effort="30.0" lower="-1.57079637" upper="1.57079637" velocity="6.28318548"/>
  </joint>
  <link name="bogie_left_link">
    <visual>
      <origin rpy="0 0 0" xyz="0 0 0"/>
      <geometry>
        <mesh filename="package://fr01_description/meshes/visual/bogie_left_link.dae"/>
      </geometry>
    </visual>
    <collision>
      <origin rpy="0 0 0" xyz="0 0 0"/>
      <geometry>
        <mesh filename="package://fr01_description/meshes/collision/bogie_left_link.stl"/>
      </geometry>
    </collision>
    <inertial>
      <mass value="3.374"/>
      <inertia ixx="0.002" ixy="-0.0000006528" ixz="-0.000002349" iyy="0.002" iyz="0.0000001156" izz="0.003"/>
    </inertial>
  </link>
  <!-- Steer -->
  <joint name="steer_right_front_joint" type="revolute">
    <origin rpy="0 0 -1.57079637" xyz="-0.202 0.115 0.05"/>
    <parent link="bogie_right_link"/>
    <child link="steer_right_front_link"/>
    <axis xyz="0 0 1"/>
    <dynamics dampint="0.7" friction="0.7"/>
    <limit effort="30.0" lower="-1.57079637" upper="1.57079637" velocity="6.28318548"/>
  </joint>
  <link name="steer_right_front_link">
    <visual>
      <origin rpy="0 0 0" xyz="0 0 0"/>
      <geometry>
        <mesh filename="package://fr01_description/meshes/visual/steer_link.dae"/>
      </geometry>
    </visual>
    <collision>
      <origin rpy="0 0 0" xyz="0 0 0"/>
      <geometry>
        <mesh filename="package://fr01_description/meshes/collision/steer_link.stl"/>
      </geometry>
    </collision>
    <inertial>
      <mass value="2.522"/>
      <inertia ixx="0.0005737" ixy="0.0000000001174" ixz="0.0000003442" iyy="0.002" iyz="-0.0000000007199" izz="0.002"/>
    </inertial>
  </link>
  <joint name="steer_right_back_joint" type="revolute">
    <origin rpy="0 0 1.57079637" xyz="-0.4 -0.05 -0.1"/>
    <parent link="rocker_right_link"/>
    <child link="steer_right_back_link"/>
    <axis xyz="0 0 1"/>
    <dynamics dampint="0.7" friction="0.7"/>
    <limit effort="30.0" lower="-1.57079637" upper="1.57079637" velocity="6.28318548"/>
  </joint>
  <link name="steer_right_back_link">
    <visual>
      <origin rpy="0 0 0" xyz="0 0 0"/>
      <geometry>
        <mesh filename="package://fr01_description/meshes/visual/steer_link.dae"/>
      </geometry>
    </visual>
    <collision>
      <origin rpy="0 0 0" xyz="0 0 0"/>
      <geometry>
        <mesh filename="package://fr01_description/meshes/collision/steer_link.stl"/>
      </geometry>
    </collision>
    <inertial>
      <mass value="2.522"/>
      <inertia ixx="0.0005737" ixy="0.0000000001174" ixz="0.0000003442" iyy="0.002" iyz="-0.0000000007199" izz="0.002"/>
    </inertial>
  </link>
  <joint name="steer_left_front_joint" type="revolute">
    <origin rpy="0 0 1.57079637" xyz="-0.202 -0.115 0.05"/>
    <parent link="bogie_left_link"/>
    <child link="steer_left_front_link"/>
    <axis xyz="0 0 1"/>
    <dynamics dampint="0.7" friction="0.7"/>
    <limit effort="30.0" lower="-1.57079637" upper="1.57079637" velocity="6.28318548"/>
  </joint>
  <link name="steer_left_front_link">
    <visual>
      <origin rpy="0 0 0" xyz="0 0 0"/>
      <geometry>
        <mesh filename="package://fr01_description/meshes/visual/steer_link.dae"/>
      </geometry>
    </visual>
    <collision>
      <origin rpy="0 0 0" xyz="0 0 0"/>
      <geometry>
        <mesh filename="package://fr01_description/meshes/collision/steer_link.stl"/>
      </geometry>
    </collision>
    <inertial>
      <mass value="2.522"/>
      <inertia ixx="0.0005737" ixy="0.0000000001174" ixz="0.0000003442" iyy="0.002" iyz="-0.0000000007199" izz="0.002"/>
    </inertial>
  </link>
  <joint name="steer_left_back_joint" type="revolute">
    <origin rpy="0 0 -1.57079637" xyz="-0.4 0.05 -0.1"/>
    <parent link="rocker_left_link"/>
    <child link="steer_left_back_link"/>
    <axis xyz="0 0 1"/>
    <dynamics dampint="0.7" friction="0.7"/>
    <limit effort="30.0" lower="-1.57079637" upper="1.57079637" velocity="6.28318548"/>
  </joint>
  <link name="steer_left_back_link">
    <visual>
      <origin rpy="0 0 0" xyz="0 0 0"/>
      <geometry>
        <mesh filename="package://fr01_description/meshes/visual/steer_link.dae"/>
      </geometry>
    </visual>
    <collision>
      <origin rpy="0 0 0" xyz="0 0 0"/>
      <geometry>
        <mesh filename="package://fr01_description/meshes/collision/steer_link.stl"/>
      </geometry>
    </collision>
    <inertial>
      <mass value="2.522"/>
      <inertia ixx="0.0005737" ixy="0.0000000001174" ixz="0.0000003442" iyy="0.002" iyz="-0.0000000007199" izz="0.002"/>
    </inertial>
  </link>
  <!-- Wheel -->
  <joint name="wheel_right_front_joint" type="continuous">
    <origin rpy="0 0 0" xyz="-0.065 0 -0.2145"/>
    <parent link="steer_right_front_link"/>
    <child link="wheel_right_front_link"/>
    <axis xyz="1 0 0"/>
  </joint>
  <link name="wheel_right_front_link">
    <visual>
      <origin rpy="0 0 0" xyz="0 0 0"/>
      <geometry>
        <mesh filename="package://fr01_description/meshes/visual/wheel_link.dae"/>
      </geometry>
    </visual>
    <collision>
      <origin rpy="0 0 0" xyz="0 0 0"/>
      <geometry>
        <mesh filename="package://fr01_description/meshes/collision/wheel_link.stl"/>
      </geometry>
    </collision>
    <inertial>
      <mass value="2.966"/>
      <inertia ixx="0.006" ixy="0" ixz="0" iyy="0.004" iyz="0" izz="0.004"/>
    </inertial>
  </link>
  <joint name="wheel_right_middle_joint" type="continuous">
    <origin rpy="0 0 -1.57079637" xyz="0.198 0.2485 -0.165"/>
    <parent link="bogie_right_link"/>
    <child link="wheel_right_middle_link"/>
    <axis xyz="1 0 0"/>
  </joint>
  <link name="wheel_right_middle_link">
    <visual>
      <origin rpy="0 0 0" xyz="0 0 0"/>
      <geometry>
        <mesh filename="package://fr01_description/meshes/visual/wheel_link.dae"/>
      </geometry>
    </visual>
    <collision>
      <origin rpy="0 0 0" xyz="0 0 0"/>
      <geometry>
        <mesh filename="package://fr01_description/meshes/collision/wheel_link.stl"/>
      </geometry>
    </collision>
    <inertial>
      <mass value="2.966"/>
      <inertia ixx="0.006" ixy="0" ixz="0" iyy="0.004" iyz="0" izz="0.004"/>
    </inertial>
  </link>
  <joint name="wheel_right_back_joint" type="continuous">
    <origin rpy="0 0 0" xyz="-0.065 0 -0.2145"/>
    <parent link="steer_right_back_link"/>
    <child link="wheel_right_back_link"/>
    <axis xyz="1 0 0"/>
  </joint>
  <link name="wheel_right_back_link">
    <visual>
      <origin rpy="0 0 0" xyz="0 0 0"/>
      <geometry>
        <mesh filename="package://fr01_description/meshes/visual/wheel_link.dae"/>
      </geometry>
    </visual>
    <collision>
      <origin rpy="0 0 0" xyz="0 0 0"/>
      <geometry>
        <mesh filename="package://fr01_description/meshes/collision/wheel_link.stl"/>
      </geometry>
    </collision>
    <inertial>
      <mass value="2.966"/>
      <inertia ixx="0.006" ixy="0" ixz="0" iyy="0.004" iyz="0" izz="0.004"/>
    </inertial>
  </link>
  <joint name="wheel_left_front_joint" type="continuous">
    <origin rpy="0 0 0" xyz="-0.065 0 -0.2145"/>
    <parent link="steer_left_front_link"/>
    <child link="wheel_left_front_link"/>
    <axis xyz="1 0 0"/>
  </joint>
  <link name="wheel_left_front_link">
    <visual>
      <origin rpy="0 0 0" xyz="0 0 0"/>
      <geometry>
        <mesh filename="package://fr01_description/meshes/visual/wheel_link.dae"/>
      </geometry>
    </visual>
    <collision>
      <origin rpy="0 0 0" xyz="0 0 0"/>
      <geometry>
        <mesh filename="package://fr01_description/meshes/collision/wheel_link.stl"/>
      </geometry>
    </collision>
    <inertial>
      <mass value="2.966"/>
      <inertia ixx="0.006" ixy="0" ixz="0" iyy="0.004" iyz="0" izz="0.004"/>
    </inertial>
  </link>
  <joint name="wheel_left_middle_joint" type="continuous">
    <origin rpy="0 0 1.57079637" xyz="0.198 -0.2485 -0.165"/>
    <parent link="bogie_left_link"/>
    <child link="wheel_left_middle_link"/>
    <axis xyz="1 0 0"/>
  </joint>
  <link name="wheel_left_middle_link">
    <visual>
      <origin rpy="0 0 0" xyz="0 0 0"/>
      <geometry>
        <mesh filename="package://fr01_description/meshes/visual/wheel_link.dae"/>
      </geometry>
    </visual>
    <collision>
      <origin rpy="0 0 0" xyz="0 0 0"/>
      <geometry>
        <mesh filename="package://fr01_description/meshes/collision/wheel_link.stl"/>
      </geometry>
    </collision>
    <inertial>
      <mass value="2.966"/>
      <inertia ixx="0.006" ixy="0" ixz="0" iyy="0.004" iyz="0" izz="0.004"/>
    </inertial>
  </link>
  <joint name="wheel_left_back_joint" type="continuous">
    <origin rpy="0 0 0" xyz="-0.065 0 -0.2145"/>
    <parent link="steer_left_back_link"/>
    <child link="wheel_left_back_link"/>
    <axis xyz="1 0 0"/>
  </joint>
  <link name="wheel_left_back_link">
    <visual>
      <origin rpy="0 0 0" xyz="0 0 0"/>
      <geometry>
        <mesh filename="package://fr01_description/meshes/visual/wheel_link.dae"/>
      </geometry>
    </visual>
    <collision>
      <origin rpy="0 0 0" xyz="0 0 0"/>
      <geometry>
        <mesh filename="package://fr01_description/meshes/collision/wheel_link.stl"/>
      </geometry>
    </collision>
    <inertial>
      <mass value="2.966"/>
      <inertia ixx="0.006" ixy="0" ixz="0" iyy="0.004" iyz="0" izz="0.004"/>
    </inertial>
  </link>
  <link name="base_footprint"/>
  <joint name="base_footprint_joint" type="fixed">
    <origin rpy="0 0 0" xyz="0 0.213 -0.398"/>
    <parent link="rocker_right_link"/>
    <child link="base_footprint"/>
  </joint>
  <!--==================== Transmission ====================-->
  <!-- base_stabilized -->
  <transmission name="base_stabilized_trans">
    <type>transmission_interface/SimpleTransmission</type>
    <joint name="base_link_joint">
      <hardwareInterface>EffortJointInterface</hardwareInterface>
    </joint>
    <actuator name="base_link_joint_motor">
      <hardwareInterface>EffortJointInterface</hardwareInterface>
      <mechanicalReduction>1</mechanicalReduction>
    </actuator>
  </transmission>
  <!-- Rocker -->
  <transmission name="rocker_right_trans">
    <type>transmission_interface/SimpleTransmission</type>
    <joint name="rocker_right_joint">
      <hardwareInterface>EffortJointInterface</hardwareInterface>
    </joint>
    <actuator name="rocker_right_motor">
      <hardwareInterface>EffortJointInterface</hardwareInterface>
      <mechanicalReduction>1</mechanicalReduction>
    </actuator>
  </transmission>
  <transmission name="rocker_left_trans">
    <type>transmission_interface/SimpleTransmission</type>
    <joint name="rocker_left_joint">
      <hardwareInterface>EffortJointInterface</hardwareInterface>
    </joint>
    <actuator name="rocker_left_motor">
      <hardwareInterface>EffortJointInterface</hardwareInterface>
      <mechanicalReduction>1</mechanicalReduction>
    </actuator>
  </transmission>
  <!-- Bogie -->
  <transmission name="bogie_right_trans">
    <type>transmission_interface/SimpleTransmission</type>
    <joint name="bogie_right_joint">
      <hardwareInterface>EffortJointInterface</hardwareInterface>
    </joint>
    <actuator name="bogie_right_motor">
      <hardwareInterface>EffortJointInterface</hardwareInterface>
      <mechanicalReduction>1</mechanicalReduction>
    </actuator>
  </transmission>
  <transmission name="bogie_left_trans">
    <type>transmission_interface/SimpleTransmission</type>
    <joint name="bogie_left_joint">
      <hardwareInterface>EffortJointInterface</hardwareInterface>
    </joint>
    <actuator name="bogie_left_motor">
      <hardwareInterface>EffortJointInterface</hardwareInterface>
      <mechanicalReduction>1</mechanicalReduction>
    </actuator>
  </transmission>
  <!-- Steer -->
  <transmission name="steer_right_front_trans">
    <type>transmission_interface/SimpleTransmission</type>
    <joint name="steer_right_front_joint">
      <hardwareInterface>EffortJointInterface</hardwareInterface>
    </joint>
    <actuator name="steer_right_front_motor">
      <hardwareInterface>EffortJointInterface</hardwareInterface>
      <mechanicalReduction>1</mechanicalReduction>
    </actuator>
  </transmission>
  <transmission name="steer_right_back_trans">
    <type>transmission_interface/SimpleTransmission</type>
    <joint name="steer_right_back_joint">
      <hardwareInterface>EffortJointInterface</hardwareInterface>
    </joint>
    <actuator name="steer_right_back_motor">
      <hardwareInterface>EffortJointInterface</hardwareInterface>
      <mechanicalReduction>1</mechanicalReduction>
    </actuator>
  </transmission>
  <transmission name="steer_left_front_trans">
    <type>transmission_interface/SimpleTransmission</type>
    <joint name="steer_left_front_joint">
      <hardwareInterface>EffortJointInterface</hardwareInterface>
    </joint>
    <actuator name="steer_left_front_motor">
      <hardwareInterface>EffortJointInterface</hardwareInterface>
      <mechanicalReduction>1</mechanicalReduction>
    </actuator>
  </transmission>
  <transmission name="steer_left_back_trans">
    <type>transmission_interface/SimpleTransmission</type>
    <joint name="steer_left_back_joint">
      <hardwareInterface>EffortJointInterface</hardwareInterface>
    </joint>
    <actuator name="steer_left_back_motor">
      <hardwareInterface>EffortJointInterface</hardwareInterface>
      <mechanicalReduction>1</mechanicalReduction>
    </actuator>
  </transmission>
  <!-- Wheel -->
  <transmission name="wheel_right_front_trans">
    <type>transmission_interface/SimpleTransmission</type>
    <joint name="wheel_right_front_joint">
      <hardwareInterface>EffortJointInterface</hardwareInterface>
    </joint>
    <actuator name="wheel_right_front_motor">
      <hardwareInterface>EffortJointInterface</hardwareInterface>
      <mechanicalReduction>50</mechanicalReduction>
    </actuator>
  </transmission>
  <transmission name="wheel_right_middle_trans">
    <type>transmission_interface/SimpleTransmission</type>
    <joint name="wheel_right_middle_joint">
      <hardwareInterface>EffortJointInterface</hardwareInterface>
    </joint>
    <actuator name="wheel_right_middle_motor">
      <hardwareInterface>EffortJointInterface</hardwareInterface>
      <mechanicalReduction>50</mechanicalReduction>
    </actuator>
  </transmission>
  <transmission name="wheel_right_back_trans">
    <type>transmission_interface/SimpleTransmission</type>
    <joint name="wheel_right_back_joint">
      <hardwareInterface>EffortJointInterface</hardwareInterface>
    </joint>
    <actuator name="wheel_right_back_motor">
      <hardwareInterface>EffortJointInterface</hardwareInterface>
      <mechanicalReduction>50</mechanicalReduction>
    </actuator>
  </transmission>
  <transmission name="wheel_left_front_trans">
    <type>transmission_interface/SimpleTransmission</type>
    <joint name="wheel_left_front_joint">
      <hardwareInterface>EffortJointInterface</hardwareInterface>
    </joint>
    <actuator name="wheel_left_front_motor">
      <hardwareInterface>EffortJointInterface</hardwareInterface>
      <mechanicalReduction>50</mechanicalReduction>
    </actuator>
  </transmission>
  <transmission name="wheel_left_middle_trans">
    <type>transmission_interface/SimpleTransmission</type>
    <joint name="wheel_left_middle_joint">
      <hardwareInterface>EffortJointInterface</hardwareInterface>
    </joint>
    <actuator name="wheel_left_middle_motor">
      <hardwareInterface>EffortJointInterface</hardwareInterface>
      <mechanicalReduction>50</mechanicalReduction>
    </actuator>
  </transmission>
  <transmission name="wheel_left_back_trans">
    <type>transmission_interface/SimpleTransmission</type>
    <joint name="wheel_left_back_joint">
      <hardwareInterface>EffortJointInterface</hardwareInterface>
    </joint>
    <actuator name="wheel_left_back_motor">
      <hardwareInterface>EffortJointInterface</hardwareInterface>
      <mechanicalReduction>50</mechanicalReduction>
    </actuator>
  </transmission>
  <!--==================== Gazebo ====================-->
  <gazebo>
    <plugin filename="libgazebo_ros_control.so" name="gazebo_ros_control">
      <robotNamespace>/fr01</robotNamespace>
    </plugin>
  </gazebo>
  <!-- Body -->
  <xacro:body_gazebo_vo/>
  <!-- Rocker -->
  <gazebo reference="rocke_right_link">
    <selfCollide>true</selfCollide>
    <mu1 value="0.8"/>
    <mu2 value="0.8"/>
  </gazebo>
  <gazebo reference="rocke_left_link">
    <selfCollide>true</selfCollide>
    <mu1 value="0.8"/>
    <mu2 value="0.8"/>
  </gazebo>
  <!-- Bogie -->
  <gazebo reference="bogie_right_link">
    <selfCollide>true</selfCollide>
    <mu1 value="0.8"/>
    <mu2 value="0.8"/>
  </gazebo>
  <gazebo reference="bogie_left_link">
    <selfCollide>true</selfCollide>
    <mu1 value="0.8"/>
    <mu2 value="0.8"/>
  </gazebo>
  <!-- Steer -->
  <gazebo reference="rocke_right_front_link">
    <selfCollide>true</selfCollide>
    <mu1 value="0.8"/>
    <mu2 value="0.8"/>
  </gazebo>
  <gazebo reference="rocke_right_back_link">
    <selfCollide>true</selfCollide>
    <mu1 value="0.8"/>
    <mu2 value="0.8"/>
  </gazebo>
  <gazebo reference="rocke_left_front_link">
    <selfCollide>true</selfCollide>
    <mu1 value="0.8"/>
    <mu2 value="0.8"/>
  </gazebo>
  <gazebo reference="rocke_left_back_link">
    <selfCollide>true</selfCollide>
    <mu1 value="0.8"/>
    <mu2 value="0.8"/>
  </gazebo>
  <!-- Wheel -->
  <gazebo reference="wheel_right_front_link">
    <selfCollide>true</selfCollide>
    <mu1 value="0.8"/>
    <mu2 value="0.8"/>
  </gazebo>
  <gazebo reference="wheel_right_middle_link">
    <selfCollide>true</selfCollide>
    <mu1 value="0.8"/>
    <mu2 value="0.8"/>
  </gazebo>
  <gazebo reference="wheel_right_back_link">
    <selfCollide>true</selfCollide>
    <mu1 value="0.8"/>
    <mu2 value="0.8"/>
  </gazebo>
  <gazebo reference="wheel_left_front_link">
    <selfCollide>true</selfCollide>
    <mu1 value="0.8"/>
    <mu2 value="0.8"/>
  </gazebo>
  <gazebo reference="wheel_left_middle_link">
    <selfCollide>true</selfCollide>
    <mu1 value="0.8"/>
    <mu2 value="0.8"/>
  </gazebo>
  <gazebo reference="wheel_left_back_link">
    <selfCollide>true</selfCollide>
    <mu1 value="0.8"/>
    <mu2 value="0.8"/>
  </gazebo>
</robot>

